Workbook
Name AC_DEPOSITS: #REF!
Name ACRegion: #REF!
Name ACT1_LF: #REF!
Name ACT2_LF: #REF!
Name AMZ_OTHER: #REF!
Name AMZ_OTHER_CC: #REF!
Name AMZ_STATIONS: #REF!
Name AMZ_TO: #REF!
Name AMZ_WAGES: #REF!
Name AMZ_WAGES_CC: #REF!
Name amzAOs: #REF!
Name ANC_INCREASE_All_Markets: #REF!
Name AO_GA: #REF!
Name ATR72_LF: #REF!
Name AVG_BH_CAR_PIL: #REF!
Name AVG_BH_PIL: #REF!
Name BB_DEPR: #REF!
Name BB_GA_Salaries: #REF!
Name BB_OTHER: #REF!
Name BB_SALARIES: #REF!
Name BB_Wages: #REF!
Name CA_Rate: #REF!
Name CARGO_Pilots: #REF!
Name ColumnsIntoTable: CHOOSE({1,2},#REF!,#REF!)
Name ColumnsIntoTable: CHOOSE({1,2},#REF!,#REF!)
Name ColumnsIntoTable: CHOOSE({1,2},#REF!,#REF!)
Name ColumnsIntoTable: CHOOSE({1,2},#REF!,#REF!)
Name ColumnsIntoTable: CHOOSE({1,2},#REF!,#REF!)
Name COMM_BB_Incr: #REF!
Name COMM_BB_TOTAL: #REF!
Name COMM_Sil_Incr: #REF!
Name COMM_Silver_TOTAL: #REF!
Name Delivery_Month_OPLEASE: #REF!
Name Fare_change: #REF!
Name Flying_Attrition: #REF!
Name FO_Rate: #REF!
Name FUELTREND: #REF!
Name GA_Salaries: #REF!
Name GOODWILL: #REF!
Name HVYCHK_REIMB_RESERVES: #REF!
Name INTANGIBLE_ACC_AMORT: #REF!
Name IQ_CH: 110000
Name IQ_CQ: 5000
Name IQ_CY: 10000
Name IQ_DAILY: 500000
Name IQ_FH: 100000
Name IQ_FQ: 500
Name IQ_FY: 1000
Name IQ_LTM: 2000
Name IQ_MONTH: 15000
Name IQ_NTM: 6000
Name IQ_WEEK: 50000
Name IQ_YTD: 3000
Name IS_Seaborne_YR: #REF!
Name IS_Silver_YR: #REF!
Name LESS_ACC_DEPR: #REF!
Name LOAD_FACTOR_ADJUSTMENTS: #REF!
Name MAINT_BB_TOTAL: #REF!
Name MAINT_SIL_TOTAL: #REF!
Name MONTHLY_BAL: #REF!

Sheet basic
D1: avion 1 | G1: avion 2 | L1: avion 1 | O1: avion 2 | T1: avion 1 | W1: avion 2 | Z1: avion 3 | AC1: avion 4
B2: vuelo | C2: ruta | D2: horas | E2: kg | F2: ruta | G2: horas | H2: kg | J2: vuelo | K2: ruta | L2: horas | M2: kg | N2: ruta | O2: horas | P2: kg | R2: vuelo | S2: ruta | T2: horas | U2: kg | V2: ruta | W2: horas | X2: kg | Y2: ruta | Z2: horas | AA2: kg | AB2: ruta | AC2: horas | AD2: kg
B3: 1 | C3: mde-kin | D3: 2.5 | E3: 24000 | F3: mia kin | G3: 2.5 | H3: 24000 | J3: 1 | K3: mde-kin | L3: 2.5 | M3: 24000 | N3: mia kin | O3: 2.5 | P3: 24000 | R3: 1 | S3: mde-kin | T3: 2.5 | U3: 24000 | V3: mia kin | W3: 2.5 | X3: 24000 | Y3: mia kin | Z3: 2.5 | AA3: 24000 | AB3: gso eur | AC3: 12 | AD3: 102000
B4: 2 | C4: kin-mde | D4: 2.5 | F4: kin-mia | G4: 2.5 | J4: 2 | K4: kin-mde | L4: 2.5 | N4: kin-mia | O4: 2.5 | R4: 2 | S4: kin-mde | T4: 2.5 | V4: kin-mia | W4: 2.5 | Y4: kin-mia | Z4: 2.5 | AB4: eur gso | AC4: 12 | AD4: 102000
B5: 3 | C5: mde- mia | D5: 3 | E5: 24000 | J5: 3 | K5: mde- mia | L5: 3 | M5: 24000 | R5: 3 | S5: mde- mia | T5: 3 | U5: 24000
B6: 4 | C6: mia mde | D6: 3 | E6: 12000 | J6: 4 | K6: mia mde | L6: 3 | M6: 12000 | R6: 4 | S6: mia mde | T6: 3 | U6: 12000
B9: total | D9: =SUM(D3:D8) -> 11 | E9: =SUM(E3:E8) -> 60000 | G9: =SUM(G3:G8) -> 5 | H9: =SUM(H3:H8) -> 24000 | J9: total | L9: =SUM(L3:L8) -> 11 | M9: =SUM(M3:M8) -> 60000 | O9: =SUM(O3:O8) -> 5 | P9: =SUM(P3:P8) -> 24000 | R9: total | T9: =SUM(T3:T8) -> 11 | U9: =SUM(U3:U8) -> 60000 | W9: =SUM(W3:W8) -> 5 | X9: =SUM(X3:X8) -> 24000 | Z9: =SUM(Z3:Z8) -> 5 | AA9: =SUM(AA3:AA8) -> 24000 | AC9: =SUM(AC3:AC8) -> 24 | AD9: =SUM(AD3:AD8) -> 204000
E10: dia | F10: 1 | G10: =D9+G9 -> 16 | H10: =E9+H9 -> 84000 | M10: dia | N10: 1 | O10: =L9+O9 -> 16 | P10: =M9+P9 -> 84000 | X10: dia | Y10: 1 | Z10: =T9+W9+Z9 -> 21 | AA10: =U9+X9+AA9 -> 108000 | AB10: 1 | AC10: =AC9*Y10 -> 24 | AD10: =AD9*AB10 -> 204000
E11: semana | F11: 6 | G11: =G10*F11 -> 96 | H11: =H10*F11 -> 504000 | M11: semana | N11: 7 | O11: =O10*N11 -> 112 | P11: =P10*N11 -> 588000 | X11: semana | Y11: 7 | Z11: =Z10*Y11 -> 147 | AA11: =AA10*Y11 -> 756000 | AB11: 2 | AC11: =AC10*AB11 -> 48 | AD11: =AD10*AB11 -> 408000
E12: mes | F12: 4 | G12: =G11*F12 -> 384 | H12: =H11*F12 -> 2016000 | M12: mes | N12: 4 | O12: =O11*N12 -> 448 | P12: =P11*N12 -> 2352000 | X12: mes | Y12: 4 | Z12: =Z11*Y12 -> 588 | AA12: =AA11*Y12 -> 3024000 | AB12: 4 | AC12: =AC11*AB12 -> 192 | AD12: =AD11*AB12 -> 1632000
E13: ano | F13: 12 | G13: =G12*F13 -> 4608 | H13: =H12*F13 -> 24192000 | M13: ano | N13: 12 | O13: =O12*N13 -> 5376 | P13: =P12*N13 -> 28224000 | X13: ano | Y13: 12 | Z13: =Z12*Y13 -> 7056 | AA13: =AA12*Y13 -> 36288000 | AB13: 12 | AC13: =AC12*AB13 -> 2304 | AD13: =AD12*AB13 -> 19584000
E14: total costoS | G14: =G13*variables!$C$3 -> 41472000 | H14: =H13*variables!$C$5 -> 72576000 | M14: total costoS | O14: =O13*variables!$C$3 -> 48384000 | P14: =P13*variables!$C$5 -> 84672000 | X14: total costoS | Z14: =Z13*variables!$C$3 -> 63504000 | AA14: =AA13*variables!$C$5 -> 108864000 | AC14: =AC13*variables!$D$3 -> 41472000 | AD14: =AD13*variables!$C$5 -> 58752000
E15: utilidad | G15: =G14/H13 -> 1.7142857 | H15: =H13*variables!$C$6 -> 48384000 | M15: utilidad | O15: =O14/P13 -> 1.7142857 | P15: =P13*variables!$C$6 -> 56448000 | X15: utilidad | Z15: =Z14/AA13 -> 1.75 | AA15: =AA13*variables!$C$6 -> 72576000 | AC15: =AC14/AD13 -> 2.1176471 | AD15: =AD13*variables!$D$6 -> 34272000
E16: total | H16: =G14+H14+H15 -> 162432000 | M16: total | P16: =O14+P14+P15 -> 189504000 | X16: total | AA16: =Z14+AA14+AA15 -> 244944000 | AD16: =AC14+AD14+AD15 -> 134496000
B18: vuelo | C18: ruta | D18: horas | E18: kg | F18: ruta | G18: horas | H18: kg | J18: vuelo | K18: ruta | L18: horas | M18: kg | N18: ruta | O18: horas | P18: kg | R18: vuelo | S18: ruta | T18: horas | U18: kg | V18: ruta | W18: horas | X18: kg | Y18: ruta | Z18: horas | AA18: kg
B19: 5 | F19: mde- mia | G19: 3 | H19: 24000 | J19: 5 | K19: mde- mia | L19: 3 | M19: 24000 | N19: mde- mia | O19: 3 | P19: 24000 | R19: 5 | S19: mde- mia | T19: 3 | U19: 24000 | Y19: mde- mia | Z19: 3 | AA19: 24000
B20: 6 | F20: mia mde | G20: 3 | H20: 12000 | J20: 6 | K20: mia mde | L20: 3 | M20: 12000 | R20: 6 | S20: mia mde | T20: 3 | U20: 12000 | Y20: mia mde | Z20: 3 | AA20: 12000
B22: total | D22: =SUM(D19:D21) -> 0 | E22: =SUM(E19:E21) -> 0 | F22: =SUM(F19:F21) -> 0 | G22: =SUM(G19:G21) -> 6 | H22: =SUM(H19:H21) -> 36000 | J22: total | L22: =SUM(L19:L21) -> 6 | M22: =SUM(M19:M21) -> 36000 | N22: =SUM(N19:N21) -> 0 | O22: =SUM(O19:O21) -> 3 | P22: =SUM(P19:P21) -> 24000 | R22: total | T22: =SUM(T19:T21) -> 6 | U22: =SUM(U19:U21) -> 36000 | V22: =SUM(V19:V21) -> 0 | W22: =SUM(W19:W21) -> 0 | X22: =SUM(X19:X21) -> 0 | Z22: =SUM(Z19:Z21) -> 6 | AA22: =SUM(AA19:AA21) -> 36000
E23: dia | F23: 1 | G23: =D22+G22 -> 6 | H23: =E22+H22 -> 36000 | M23: dia | N23: 1 | O23: =L22+O22 -> 9 | P23: =M22+P22 -> 60000 | X23: dia | Y23: 1 | Z23: =T22+W22+Z22 -> 12 | AA23: =U22+X22+AA22 -> 72000
E24: semana | F24: 7 | G24: =G23*F24 -> 42 | H24: =H23*F24 -> 252000 | M24: semana | N24: 7 | O24: =O23*N24 -> 63 | P24: =P23*N24 -> 420000 | T24: =T9+W9+Z9+Z22+W22+T22 -> 33 | X24: semana | Y24: 7 | Z24: =Z23*Y24 -> 84 | AA24: =AA23*Y24 -> 504000
E25: mes | F25: 4 | G25: =G24*F25 -> 168 | H25: =H24*F25 -> 1008000 | M25: mes | N25: 4 | O25: =O24*N25 -> 252 | P25: =P24*N25 -> 1680000 | X25: mes | Y25: 4 | Z25: =Z24*Y25 -> 336 | AA25: =AA24*Y25 -> 2016000
E26: ano | F26: 12 | G26: =G25*F26 -> 2016 | H26: =H25*F26 -> 12096000 | M26: ano | N26: 12 | O26: =O25*N26 -> 3024 | P26: =P25*N26 -> 20160000 | X26: ano | Y26: 12 | Z26: =Z25*Y26 -> 4032 | AA26: =AA25*Y26 -> 24192000
E27: total costoS | G27: =G26*variables!$C$3 -> 18144000 | M27: total costoS | O27: =O26*variables!$C$3 -> 27216000 | X27: total costoS | Z27: =Z26*variables!$C$4 -> 40320000
E28: utilidad | G28: =G27/H26 -> 1.5 | M28: utilidad | O28: =O27/P26 -> 1.35 | X28: utilidad | Y28: =Z27/AA26 -> 1.6666667
E29: total | H29: =G27+H27+H28 -> 18144000 | M29: total | P29: =O27+P27+P28 -> 27216000 | X29: total | AA29: =Z27+AA27+AA28 -> 40320000
E31: total | G31: =G26+G13 -> 6624 | H31: =H26+H13 -> 36288000 | M31: total | O31: =O26+O13 -> 8400 | P31: =P26+P13 -> 48384000 | X31: total 321 | Z31: =Z26+Z13 -> 11088 | AA31: =AA26+AA13 -> 60480000 | AB31: total b777 | AC31: =AC13 -> 2304 | AD31: =AD13 -> 19584000
W33: a321 | X33: b777
F34: fuel cost | G34: =G31*variables!$C$11*variables!$C$12 -> 17884800 | N34: fuel cost | O34: =O31*variables!$C$11*variables!$C$12 -> 22680000 | V34: fuel cost | W34: =Z31*variables!$C$11*variables!$C$12 -> 29937600 | X34: =AC31*variables!$D$11*variables!$C$12 -> 12441600 | Y34: =SUM(W34:X34) -> 42379200
F35: cargo hand | H35: =H31*variables!$C$9 -> 3628800 | N35: cargo hand | P35: =P31*variables!$C$9 -> 4838400 | V35: cargo hand | W35: =AA31*variables!$C$9 -> 6048000 | X35: =AD31*variables!$C$9 -> 1958400 | Y35: =SUM(W35:X35) -> 8006400
F36: sobrevuelo | G36: =G31*variables!$C$13*variables!$C$10 -> 1159200 | N36: sobrevuelo | O36: =O31*variables!$C$13*variables!$C$10 -> 1470000 | V36: sobrevuelo | W36: =Z31*variables!$C$13*variables!$C$10 -> 1940400 | X36: =AC31*variables!$C$13*variables!$C$10 -> 403200 | Y36: =SUM(W36:X36) -> 2343600
F37: mantenimiento | G37: =G31*variables!$C$14 -> 9936000 | N37: mantenimiento | O37: =O31*variables!$C$14 -> 12600000 | V37: mantenimiento | W37: =Z31*variables!$C$14 -> 16632000 | X37: =AC31*variables!$D$14 -> 14976000 | Y37: =SUM(W37:X37) -> 31608000
W41: =400000/26 -> 15384.615
D46: avion 1 | G46: avion 2 | J46: avion 3 | M46: avion 4
B47: vuelo | C47: ruta | D47: horas | E47: kg | F47: ruta | G47: horas | H47: kg | I47: ruta | J47: horas | K47: kg | L47: ruta | M47: horas | N47: kg
B48: 1 | C48: mde-kin | D48: 2.5 | E48: 24000 | F48: mia kin | G48: 2.5 | H48: 24000 | I48: mia kin | J48: 2.5 | K48: 24000 | L48: gso eur | M48: 12 | N48: 102000
B49: 2 | C49: kin-mde | D49: 2.5 | F49: kin-mia | G49: 2.5 | I49: kin-mia | J49: 2.5 | L49: eur gso | M49: 12 | N49: 102000
B50: 3 | C50: mde- mia | D50: 3 | E50: 24000 | F50: mia kin | G50: 2.5 | H50: 24000 | I50: mia kin | J50: 2.5 | K50: 24000 | L50: eur gso | M50: 12 | N50: 102000
B51: 4 | C51: mia mde | D51: 3 | E51: 12000 | F51: kin-mia | G51: 2.5 | I51: kin-mia | J51: 2.5
C52: mde- mia | D52: 3 | E52: 24000
C53: mia mde | D53: 3 | E53: 12000
...

Sheet variables
C2: A321 | D2: B777
B3: costo hora vuelo charter indirecto | C3: 9000 | D3: 18000
B4: costo hora vuelo charter indirecto gsa | C4: 10000 | D4: 20000
B5: costo kg avg productos | C5: 3
B6: utilidad avg producto | C6: 2 | D6: 1.75
B7: costo x kg venta | C7: =SUM(C5:C6) -> 5
B8: Tax provision | C8: 0.25
B9: cargo hand | C9: 0.1
B10: sobrevuelo | C10: 0.35
B11: fuel burn | C11: 900 | D11: 1800
B12: fuel cost | C12: 3
B13: millas x hora | C13: 500
B14: mant x hora | C14: 1500 | D14: 6500
A16: b777 | B16: costo hora vuelo charter indirecto

Sheet ANALYSIS
M1: FRESH | AB1: GSA | AQ1: FRESH | BG1: FRESH
E2: Fuel b. | K2: mtt x | M2: IND CHR. F24 | N2: l1 | P2: l2 | R2: l3 | T2: l4 | V2: l5 | X2: l6 | Z2: LDG | AB2: IND CHR. GSA | AC2: l1 | AE2: l2 | AG2: l3 | AI2: l4 | AK2: l5 | AM2: l6 | AQ2: total dia | AS2: TOTAL | BD2: Cargo buy | BE2: profit | BG2: total dia | BI2: TOTAL
C3: MTOW | D3: M/HORA | E3: GLS | F3: $ | G3: HAND. | H3: OVER/F | I3: LDG FEES | J3: T/A FEES | K3: HORA | N3: F/H | O3: Cargo | P3: F/H | Q3: Cargo | R3: F/H | S3: Cargo | T3: F/H | U3: Cargo | V3: F/H | W3: Cargo | X3: F/H | Y3: Cargo | AC3: F/H | AD3: Cargo | AE3: F/H | AF3: Cargo | AG3: F/H | AH3: Cargo | AI3: F/H | AJ3: Cargo | AK3: F/H | AL3: Cargo | AM3: F/H | AN3: Cargo | AO3: LDG | AQ3: F/H | AR3: Cargo | AS3: x/W | AT3: F/H (Year) | AU3: air log $ | AV3: Maint. | AW3: T/A | AX3: FUEL GLS | AY3: FUEL $ | AZ3: O/FLIGHT | BA3: LDG FEES | BB3: Cargo (Kg) | BC3: Handling | BD3: 3 | BE3: 2 | BG3: F/H | BH3: Cargo | BI3: x/W | BJ3: F/H(Year) | BK3: air log $ | BL3: Maint. | BM3: T/A | BN3: FUEL GLS | BO3: FUEL $ | BP3: O/FLIGHT | BQ3: LDG FEES | BR3: Cargo (Kg) | BS3: Handling
A4: 1 | B4: A321 | C4: 77800 | D4: 500 | E4: 900 | F4: 3 | G4: 0.1 | H4: 0.35 | I4: =C4*0.02 -> 1556 | J4: 150 | K4: 1500 | M4: 9000 | N4: 2.5 | O4: 24500 | P4: 2.5 | R4: 3 | S4: 24500 | T4: 3 | U4: 12000 | Z4: 4 | AB4: 10000 | AQ4: =N4+P4+R4+T4+V4+X4 -> 11 | AR4: =O4+Q4+S4+U4+W4+Y4 -> 61000 | AS4: 6 | AT4: =AQ4*AS4*4*12 -> 3168 | AU4: =AT4*M4 -> 28512000 | AV4: =AT4*K4 -> 4752000 | AW4: =Z4*J4*AS4*4*12 -> 172800 | AX4: =AT4*E4 -> 2851200 | AY4: =AX4*F4 -> 8553600 | AZ4: =AT4*D4*H4 -> 554400 | BA4: =Z4*I4*AS4*4*12 -> 1792512 | BB4: =AR4*AS4*4*12 -> 17568000 | BC4: =BB4*G4 -> 1756800 | BD4: =BB4*$BD$3 -> 52704000 | BE4: =BB4*$BE$3 -> 35136000 | BG4: =AC4+AE4+AG4+AI4+AK4+AM4 -> 0 | BH4: =AD4+AF4+AH4+AJ4+AL4+AN4 -> 0 | BJ4: =BG4*BI4*4*12 -> 0 | BK4: =BJ4*AB4 -> 0 | BL4: =BJ4*K4 -> 0 | BM4: =BI4*AO4*4*12*J4 -> 0 | BN4: =BJ4*E4 -> 0 | BO4: =BN4*F4 -> 0 | BP4: =BJ4*D4*H4 -> 0 | BQ4: =BI4*AO4*I4*4*12 -> 0 | BR4: =BH4*BI4*4*12 -> 0 | BS4: =BR4*G4 -> 0
A5: 1 | B5: A321 | C5: 77800 | D5: 500 | E5: 900 | F5: 3 | G5: 0.1 | H5: 0.35 | I5: =C5*0.02 -> 1556 | J5: 150 | K5: 1500 | M5: 9000 | N5: 2.5 | O5: 24500 | P5: 2.5 | Z5: 2 | AB5: 10000 | AC5: 3 | AD5: 24500 | AE5: 3 | AF5: 12000 | AO5: 2 | AQ5: =N5+P5+R5+T5+V5+X5 -> 5 | AR5: =O5+Q5+S5+U5+W5+Y5 -> 24500 | AS5: 6 | AT5: =AQ5*AS5*4*12 -> 1440 | AU5: =AT5*M5 -> 12960000 | AV5: =AT5*K5 -> 2160000 | AW5: =Z5*J5*AS5*4*12 -> 86400 | AX5: =AT5*E5 -> 1296000 | AY5: =AX5*F5 -> 3888000 | AZ5: =AT5*D5*H5 -> 252000 | BA5: =Z5*I5*AS5*4*12 -> 896256 | BB5: =AR5*AS5*4*12 -> 7056000 | BC5: =BB5*G5 -> 705600 | BD5: =BB5*$BD$3 -> 21168000 | BE5: =BB5*$BE$3 -> 14112000 | BG5: =AC5+AE5+AG5+AI5+AK5+AM5 -> 6 | BH5: =AD5+AF5+AH5+AJ5+AL5+AN5 -> 36500 | BI5: 7 | BJ5: =BG5*BI5*4*12 -> 2016 | BK5: =BJ5*AB5 -> 20160000 | BL5: =BJ5*K5 -> 3024000 | BM5: =BI5*AO5*4*12*J5 -> 100800 | BN5: =BJ5*E5 -> 1814400 | BO5: =BN5*F5 -> 5443200 | BP5: =BJ5*D5*H5 -> 352800 | BQ5: =BI5*AO5*I5*4*12 -> 1045632 | BR5: =BH5*BI5*4*12 -> 12264000 | BS5: =BR5*G5 -> 1226400
A6: 2 | B6: A321 | C6: 77800 | D6: 500 | E6: 900 | F6: 3 | G6: 0.1 | H6: 0.35 | I6: =C6*0.02 -> 1556 | J6: 150 | K6: 1500 | M6: 9000 | AB6: 10000 | AQ6: =N6+P6+R6+T6+V6+X6 -> 0 | AR6: =O6+Q6+S6+U6+W6+Y6 -> 0 | AT6: =AQ6*AS6*4*12 -> 0 | AU6: =AT6*M6 -> 0 | AV6: =AT6*K6 -> 0 | AW6: =Z6*J6*AS6*4*12 -> 0 | AX6: =AT6*E6 -> 0 | AY6: =AX6*F6 -> 0 | AZ6: =AT6*D6*H6 -> 0 | BA6: =Z6*I6*AS6*4*12 -> 0 | BB6: =AR6*AS6*4*12 -> 0 | BC6: =BB6*G6 -> 0 | BD6: =BB6*$BD$3 -> 0 | BE6: =BB6*$BE$3 -> 0 | BG6: =AC6+AE6+AG6+AI6+AK6+AM6 -> 0 | BH6: =AE6+AG6+AI6+AK6+AM6+AO6 -> 0 | BJ6: =BG6*BI6*4*12 -> 0 | BK6: =BJ6*AB6 -> 0 | BL6: =BJ6*K6 -> 0 | BM6: =BI6*AO6*4*12*J6 -> 0 | BN6: =BJ6*E6 -> 0 | BO6: =BN6*F6 -> 0 | BP6: =BJ6*D6*H6 -> 0 | BQ6: =BI6*AO6*I6*4*12 -> 0 | BR6: =BH6*BI6*4*12 -> 0 | BS6: =BR6*G6 -> 0
A7: 3 | B7: A321 | C7: 77800 | D7: 500 | E7: 900 | F7: 3 | G7: 0.1 | H7: 0.35 | I7: =C7*0.02 -> 1556 | J7: 150 | K7: 1500 | M7: 9000 | AB7: 10000 | AQ7: =N7+P7+R7+T7+V7+X7 -> 0 | AR7: =O7+Q7+S7+U7+W7+Y7 -> 0 | AT7: =AQ7*AS7*4*12 -> 0 | AU7: =AT7*M7 -> 0 | AV7: =AT7*K7 -> 0 | AW7: =Z7*J7*AS7*4*12 -> 0 | AX7: =AT7*E7 -> 0 | AY7: =AX7*F7 -> 0 | AZ7: =AT7*D7*H7 -> 0 | BA7: =Z7*I7*AS7*4*12 -> 0 | BB7: =AR7*AS7*4*12 -> 0 | BC7: =BB7*G7 -> 0 | BD7: =BB7*$BD$3 -> 0 | BE7: =BB7*$BE$3 -> 0 | BG7: =AC7+AE7+AG7+AI7+AK7+AM7 -> 0 | BH7: =AE7+AG7+AI7+AK7+AM7+AO7 -> 0 | BJ7: =BG7*BI7*4*12 -> 0 | BK7: =BJ7*AB7 -> 0 | BL7: =BJ7*K7 -> 0 | BM7: =BI7*AO7*4*12*J7 -> 0 | BN7: =BJ7*E7 -> 0 | BO7: =BN7*F7 -> 0 | BP7: =BJ7*D7*H7 -> 0 | BQ7: =BI7*AO7*I7*4*12 -> 0 | BR7: =BH7*BI7*4*12 -> 0 | BS7: =BR7*G7 -> 0
A8: 4 | B8: A321 | C8: 77800 | D8: 500 | E8: 900 | F8: 3 | G8: 0.1 | H8: 0.35 | I8: =C8*0.02 -> 1556 | J8: 150 | K8: 1500 | M8: 9000 | AB8: 10000 | AQ8: =N8+P8+R8+T8+V8+X8 -> 0 | AR8: =O8+Q8+S8+U8+W8+Y8 -> 0 | AT8: =AQ8*AS8*4*12 -> 0 | AU8: =AT8*M8 -> 0 | AV8: =AT8*K8 -> 0 | AW8: =Z8*J8*AS8*4*12 -> 0 | AX8: =AT8*E8 -> 0 | AY8: =AX8*F8 -> 0 | AZ8: =AT8*D8*H8 -> 0 | BA8: =Z8*I8*AS8*4*12 -> 0 | BB8: =AR8*AS8*4*12 -> 0 | BC8: =BB8*G8 -> 0 | BD8: =BB8*$BD$3 -> 0 | BE8: =BB8*$BE$3 -> 0 | BG8: =AC8+AE8+AG8+AI8+AK8+AM8 -> 0 | BH8: =AE8+AG8+AI8+AK8+AM8+AO8 -> 0 | BJ8: =BG8*BI8*4*12 -> 0 | BK8: =BJ8*AB8 -> 0 | BL8: =BJ8*K8 -> 0 | BM8: =BI8*AO8*4*12*J8 -> 0 | BN8: =BJ8*E8 -> 0 | BO8: =BN8*F8 -> 0 | BP8: =BJ8*D8*H8 -> 0 | BQ8: =BI8*AO8*I8*4*12 -> 0 | BR8: =BH8*BI8*4*12 -> 0 | BS8: =BR8*G8 -> 0
A9: 3 | B9: B777 | C9: 260800 | D9: 500 | E9: 1800 | F9: 3 | G9: 0.1 | H9: 0.35 | I9: =C9*0.02 -> 5216 | J9: 350 | K9: 6500 | M9: 18000 | AB9: 20000 | AQ9: =N9+P9+R9+T9+V9+X9 -> 0 | AR9: =O9+Q9+S9+U9+W9+Y9 -> 0 | AT9: =AQ9*AS9*4*12 -> 0 | AU9: =AT9*M9 -> 0 | AV9: =AT9*K9 -> 0 | AW9: =Z9*J9*AS9*4*12 -> 0 | AX9: =AT9*E9 -> 0 | AY9: =AX9*F9 -> 0 | AZ9: =AT9*D9*H9 -> 0 | BA9: =Z9*I9*AS9*4*12 -> 0 | BB9: =AR9*AS9*4*12 -> 0 | BC9: =BB9*G9 -> 0 | BD9: =BB9*$BD$3 -> 0 | BE9: =BB9*$BE$3 -> 0 | BG9: =AC9+AE9+AG9+AI9+AK9+AM9 -> 0 | BH9: =AE9+AG9+AI9+AK9+AM9+AO9 -> 0 | BJ9: =BG9*BI9*4*12 -> 0 | BK9: =BJ9*AB9 -> 0 | BL9: =BJ9*K9 -> 0 | BM9: =BI9*AO9*4*12*J9 -> 0 | BN9: =BJ9*E9 -> 0 | BO9: =BN9*F9 -> 0 | BP9: =BJ9*D9*H9 -> 0 | BQ9: =BI9*AO9*I9*4*12 -> 0 | BR9: =BH9*BI9*4*12 -> 0 | BS9: =BR9*G9 -> 0
A10: 4 | B10: B777 | C10: 260800 | D10: 500 | E10: 1800 | F10: 3 | G10: 0.1 | H10: 0.35 | I10: =C10*0.02 -> 5216 | J10: 350 | K10: 6500 | M10: 18000 | AB10: 20000 | AQ10: =N10+P10+R10+T10+V10+X10 -> 0 | AR10: =O10+Q10+S10+U10+W10+Y10 -> 0 | AT10: =AQ10*AS10*4*12 -> 0 | AU10: =AT10*M10 -> 0 | AV10: =AT10*K10 -> 0 | AW10: =Z10*J10*AS10*4*12 -> 0 | AX10: =AT10*E10 -> 0 | AY10: =AX10*F10 -> 0 | AZ10: =AT10*D10*H10 -> 0 | BA10: =Z10*I10*AS10*4*12 -> 0 | BB10: =AR10*AS10*4*12 -> 0 | BC10: =BB10*G10 -> 0 | BD10: =BB10*$BD$3 -> 0 | BE10: =BB10*$BE$3 -> 0 | BG10: =AC10+AE10+AG10+AI10+AK10+AM10 -> 0 | BH10: =AE10+AG10+AI10+AK10+AM10+AO10 -> 0 | BJ10: =BG10*BI10*4*12 -> 0 | BK10: =BJ10*AB10 -> 0 | BL10: =BJ10*K10 -> 0 | BM10: =BI10*AO10*4*12*J10 -> 0 | BN10: =BJ10*E10 -> 0 | BO10: =BN10*F10 -> 0 | BP10: =BJ10*D10*H10 -> 0 | BQ10: =BI10*AO10*I10*4*12 -> 0 | BR10: =BH10*BI10*4*12 -> 0 | BS10: =BR10*G10 -> 0
AQ11: =SUM(AQ4:AQ10) -> 16 | AT11: =SUM(AT4:AT10) -> 4608 | AU11: =SUM(AU4:AU10) -> 41472000 | AV11: =SUM(AV4:AV10) -> 6912000 | AW11: =SUM(AW4:AW10) -> 259200 | AX11: =SUM(AX4:AX10) -> 4147200 | AY11: =SUM(AY4:AY10) -> 12441600 | AZ11: =SUM(AZ4:AZ10) -> 806400 | BA11: =SUM(BA4:BA10) -> 2688768 | ... BE11: =SUM(BE4:BE10) -> 49248000 | BG11: =SUM(BG4:BG10) -> 6 | BJ11: =SUM(BJ4:BJ10) -> 2016 | BK11: =SUM(BK4:BK10) -> 20160000 | BL11: =SUM(BL4:BL10) -> 3024000 | BM11: =SUM(BM4:BM10) -> 100800 | BN11: =SUM(BN4:BN10) -> 1814400 | BO11: =SUM(BO4:BO10) -> 5443200 | BP11: =SUM(BP4:BP10) -> 352800 | BQ11: =SUM(BQ4:BQ10) -> 1045632 | ... BS11: =SUM(BS4:BS10) -> 1226400
BE12: =BD11+BE11+AU11 -> 164592000 | BJ12: =BJ11+AT11 -> 6624 | BK12: total maint | BL12: =BL11+AV11 -> 9936000 | BN12: total fuel | BO12: =BO11+AY11 -> 17884800 | BP12: TOT. AERO. | BQ12: =BQ11+BP11+BM11+BS11+BC11+BA11+AZ11+AW11 -> 8942400
M15: FRESH | AB15: GSA | AQ15: FRESH | BG15: FRESH
E16: Fuel b. | K16: mtt x | M16: IND CHR. F24 | N16: l1 | P16: l2 | R16: l3 | T16: l4 | V16: l5 | X16: l6 | Z16: LDG | AB16: IND CHR. GSA | AC16: l1 | AE16: l2 | AG16: l3 | AI16: l4 | AK16: l5 | AM16: l6 | AQ16: total dia | AS16: TOTAL | BD16: Cargo buy | BE16: profit | BG16: total dia | BI16: TOTAL
C17: MTOW | D17: M/HORA | E17: GLS | F17: $ | G17: HAND. | H17: OVER/F | I17: LDG FEES | J17: T/A FEES | K17: HORA | N17: F/H | O17: Cargo | P17: F/H | Q17: Cargo | R17: F/H | S17: Cargo | T17: F/H | U17: Cargo | V17: F/H | W17: Cargo | X17: F/H | Y17: Cargo | AC17: F/H | AD17: Cargo | AE17: F/H | AF17: Cargo | AG17: F/H | AH17: Cargo | AI17: F/H | AJ17: Cargo | AK17: F/H | AL17: Cargo | AM17: F/H | AN17: Cargo | AO17: LDG | AQ17: F/H | AR17: Cargo | AS17: x/W | AT17: F/H | AU17: air log $ | AV17: Maint. | AW17: T/A | AX17: FUEL GLS | AY17: FUEL $ | AZ17: O/FLIGHT | BA17: LDG FEES | BB17: Cargo (Kg) | BC17: Handling | BD17: 3 | BE17: 2 | BG17: F/H | BH17: Cargo | BI17: x/W | BJ17: F/H | BK17: air log $ | BL17: Maint. | BM17: T/A | BN17: FUEL GLS | BO17: FUEL $ | BP17: O/FLIGHT | BQ17: LDG FEES | BR17: Cargo (Kg) | BS17: Handling
A18: 1 | B18: A321 | C18: 77800 | D18: 500 | E18: 900 | F18: 3 | G18: 0.1 | H18: 0.35 | I18: =C18*0.02 -> 1556 | J18: 150 | K18: 1500 | M18: 9000 | N18: 2.5 | O18: 24500 | P18: 2.5 | R18: 3 | S18: 24500 | T18: 3 | U18: 12000 | Z18: 4 | AB18: 10000 | AQ18: =N18+P18+R18+T18+V18+X18 -> 11 | AR18: =O18+Q18+S18+U18+W18+Y18 -> 61000 | AS18: 7 | AT18: =AQ18*AS18*4*12 -> 3696 | AU18: =AT18*M18 -> 33264000 | AV18: =AT18*K18 -> 5544000 | AW18: =Z18*J18*AS18*4*12 -> 201600 | AX18: =AT18*E18 -> 3326400 | AY18: =AX18*F18 -> 9979200 | AZ18: =AT18*D18*H18 -> 646800 | BA18: =Z18*I18*AS18*4*12 -> 2091264 | BB18: =AR18*AS18*4*12 -> 20496000 | BC18: =BB18*G18 -> 2049600 | BD18: =BB18*$BD$17 -> 61488000 | BE18: =BB18*$BE$17 -> 40992000 | BG18: =AC18+AE18+AG18+AI18+AK18+AM18 -> 0 | BH18: =AD18+AF18+AH18+AJ18+AL18+AN18 -> 0 | BI18: 7 | BJ18: =BG18*BI18*4*12 -> 0 | BK18: =BJ18*AB18 -> 0 | BL18: =BJ18*K18 -> 0 | BM18: =BI18*AO18*4*12*J18 -> 0 | BN18: =BJ18*E18 -> 0 | BO18: =BN18*F18 -> 0 | BP18: =BJ18*D18*H18 -> 0 | BQ18: =BI18*AO18*I18*4*12 -> 0 | BR18: =BH18*BI18*4*12 -> 0 | BS18: =BR18*G18 -> 0
A19: 1 | B19: A321 | C19: 77800 | D19: 500 | E19: 900 | F19: 3 | G19: 0.1 | H19: 0.35 | I19: =C19*0.02 -> 1556 | J19: 150 | K19: 1500 | M19: 9000 | N19: 2.5 | O19: 24500 | P19: 2.5 | R19: 3 | S19: 24500 | T19: 3 | U19: 12000 | Z19: 4 | AB19: 10000 | AC19: 3 | AD19: 24500 | AE19: 3 | AF19: 12000 | AO19: 2 | AQ19: =N19+P19+R19+T19+V19+X19 -> 11 | AR19: =O19+Q19+S19+U19+W19+Y19 -> 61000 | AS19: 7 | AT19: =AQ19*AS19*4*12 -> 3696 | AU19: =AT19*M19 -> 33264000 | AV19: =AT19*K19 -> 5544000 | AW19: =Z19*J19*AS19*4*12 -> 201600 | AX19: =AT19*E19 -> 3326400 | AY19: =AX19*F19 -> 9979200 | AZ19: =AT19*D19*H19 -> 646800 | BA19: =Z19*I19*AS19*4*12 -> 2091264 | BB19: =AR19*AS19*4*12 -> 20496000 | BC19: =BB19*G19 -> 2049600 | BD19: =BB19*$BD$17 -> 61488000 | BE19: =BB19*$BE$17 -> 40992000 | BG19: =AC19+AE19+AG19+AI19+AK19+AM19 -> 6 | BH19: =AD19+AF19+AH19+AJ19+AL19+AN19 -> 36500 | BI19: 7 | BJ19: =BG19*BI19*4*12 -> 2016 | BK19: =BJ19*AB19 -> 20160000 | BL19: =BJ19*K19 -> 3024000 | BM19: =BI19*AO19*4*12*J19 -> 100800 | BN19: =BJ19*E19 -> 1814400 | BO19: =BN19*F19 -> 5443200 | BP19: =BJ19*D19*H19 -> 352800 | BQ19: =BI19*AO19*I19*4*12 -> 1045632 | BR19: =BH19*BI19*4*12 -> 12264000 | BS19: =BR19*G19 -> 1226400
A20: 2 | B20: A321 | C20: 77800 | D20: 500 | E20: 900 | F20: 3 | G20: 0.1 | H20: 0.35 | I20: =C20*0.02 -> 1556 | J20: 150 | K20: 1500 | M20: 9000 | AB20: 10000 | AC20: 3 | AD20: 24500 | AE20: 3 | AF20: 12000 | AO20: 2 | AQ20: =N20+P20+R20+T20+V20+X20 -> 0 | AR20: =O20+Q20+S20+U20+W20+Y20 -> 0 | AT20: =AQ20*AS20*4*12 -> 0 | AU20: =AT20*M20 -> 0 | AV20: =AT20*K20 -> 0 | AW20: =Z20*J20*AS20*4*12 -> 0 | AX20: =AT20*E20 -> 0 | AY20: =AX20*F20 -> 0 | AZ20: =AT20*D20*H20 -> 0 | BA20: =Z20*I20*AS20*4*12 -> 0 | BB20: =AR20*AS20*4*12 -> 0 | BC20: =BB20*G20 -> 0 | BD20: =BB20*$BD$17 -> 0 | BE20: =BB20*$BE$17 -> 0 | BG20: =AC20+AE20+AG20+AI20+AK20+AM20 -> 6 | BH20: =AE20+AG20+AI20+AK20+AM20+AO20 -> 5 | BI20: 7 | BJ20: =BG20*BI20*4*12 -> 2016 | BK20: =BJ20*AB20 -> 20160000 | BL20: =BJ20*K20 -> 3024000 | BM20: =BI20*AO20*4*12*J20 -> 100800 | BN20: =BJ20*E20 -> 1814400 | BO20: =BN20*F20 -> 5443200 | BP20: =BJ20*D20*H20 -> 352800 | BQ20: =BI20*AO20*I20*4*12 -> 1045632 | BR20: =BH20*BI20*4*12 -> 1680 | BS20: =BR20*G20 -> 168
A21: 3 | B21: A321 | C21: 77800 | D21: 500 | E21: 900 | F21: 3 | G21: 0.1 | H21: 0.35 | I21: =C21*0.02 -> 1556 | J21: 150 | K21: 1500 | M21: 9000 | AB21: 10000 | AQ21: =N21+P21+R21+T21+V21+X21 -> 0 | AR21: =O21+Q21+S21+U21+W21+Y21 -> 0 | AT21: =AQ21*AS21*4*12 -> 0 | AU21: =AT21*M21 -> 0 | AV21: =AT21*K21 -> 0 | AW21: =Z21*J21*AS21*4*12 -> 0 | AX21: =AT21*E21 -> 0 | AY21: =AX21*F21 -> 0 | AZ21: =AT21*D21*H21 -> 0 | BA21: =Z21*I21*AS21*4*12 -> 0 | BB21: =AR21*AS21*4*12 -> 0 | BC21: =BB21*G21 -> 0 | BD21: =BB21*$BD$17 -> 0 | BE21: =BB21*$BE$17 -> 0 | BG21: =AC21+AE21+AG21+AI21+AK21+AM21 -> 0 | BH21: =AE21+AG21+AI21+AK21+AM21+AO21 -> 0 | BJ21: =BG21*BI21*4*12 -> 0 | BK21: =BJ21*AB21 -> 0 | BL21: =BJ21*K21 -> 0 | BM21: =BI21*AO21*4*12*J21 -> 0 | BN21: =BJ21*E21 -> 0 | BO21: =BN21*F21 -> 0 | BP21: =BJ21*D21*H21 -> 0 | BQ21: =BI21*AO21*I21*4*12 -> 0 | BR21: =BH21*BI21*4*12 -> 0 | BS21: =BR21*G21 -> 0
A22: 4 | B22: A321 | C22: 77800 | D22: 500 | E22: 900 | F22: 3 | G22: 0.1 | H22: 0.35 | I22: =C22*0.02 -> 1556 | J22: 150 | K22: 1500 | M22: 9000 | AB22: 10000 | AQ22: =N22+P22+R22+T22+V22+X22 -> 0 | AR22: =O22+Q22+S22+U22+W22+Y22 -> 0 | AT22: =AQ22*AS22*4*12 -> 0 | AU22: =AT22*M22 -> 0 | AV22: =AT22*K22 -> 0 | AW22: =Z22*J22*AS22*4*12 -> 0 | AX22: =AT22*E22 -> 0 | AY22: =AX22*F22 -> 0 | AZ22: =AT22*D22*H22 -> 0 | BA22: =Z22*I22*AS22*4*12 -> 0 | BB22: =AR22*AS22*4*12 -> 0 | BC22: =BB22*G22 -> 0 | BD22: =BB22*$BD$17 -> 0 | BE22: =BB22*$BE$17 -> 0 | BG22: =AC22+AE22+AG22+AI22+AK22+AM22 -> 0 | BH22: =AE22+AG22+AI22+AK22+AM22+AO22 -> 0 | BJ22: =BG22*BI22*4*12 -> 0 | BK22: =BJ22*AB22 -> 0 | BL22: =BJ22*K22 -> 0 | BM22: =BI22*AO22*4*12*J22 -> 0 | BN22: =BJ22*E22 -> 0 | BO22: =BN22*F22 -> 0 | BP22: =BJ22*D22*H22 -> 0 | BQ22: =BI22*AO22*I22*4*12 -> 0 | BR22: =BH22*BI22*4*12 -> 0 | BS22: =BR22*G22 -> 0
A23: 3 | B23: B777 | C23: 260800 | D23: 500 | E23: 1800 | F23: 3 | G23: 0.1 | H23: 0.35 | I23: =C23*0.02 -> 5216 | J23: 350 | K23: 6500 | M23: 18000 | AB23: 20000 | AQ23: =N23+P23+R23+T23+V23+X23 -> 0 | AR23: =O23+Q23+S23+U23+W23+Y23 -> 0 | AT23: =AQ23*AS23*4*12 -> 0 | AU23: =AT23*M23 -> 0 | AV23: =AT23*K23 -> 0 | AW23: =Z23*J23*AS23*4*12 -> 0 | AX23: =AT23*E23 -> 0 | AY23: =AX23*F23 -> 0 | AZ23: =AT23*D23*H23 -> 0 | BA23: =Z23*I23*AS23*4*12 -> 0 | BB23: =AR23*AS23*4*12 -> 0 | BC23: =BB23*G23 -> 0 | BD23: =BB23*$BD$17 -> 0 | BE23: =BB23*$BE$17 -> 0 | BG23: =AC23+AE23+AG23+AI23+AK23+AM23 -> 0 | BH23: =AE23+AG23+AI23+AK23+AM23+AO23 -> 0 | BJ23: =BG23*BI23*4*12 -> 0 | BK23: =BJ23*AB23 -> 0 | BL23: =BJ23*K23 -> 0 | BM23: =BI23*AO23*4*12*J23 -> 0 | BN23: =BJ23*E23 -> 0 | BO23: =BN23*F23 -> 0 | BP23: =BJ23*D23*H23 -> 0 | BQ23: =BI23*AO23*I23*4*12 -> 0 | BR23: =BH23*BI23*4*12 -> 0 | BS23: =BR23*G23 -> 0
A24: 4 | B24: B777 | C24: 260800 | D24: 500 | E24: 1800 | F24: 3 | G24: 0.1 | H24: 0.35 | I24: =C24*0.02 -> 5216 | J24: 350 | K24: 6500 | M24: 18000 | AB24: 20000 | AQ24: =N24+P24+R24+T24+V24+X24 -> 0 | AR24: =O24+Q24+S24+U24+W24+Y24 -> 0 | AT24: =AQ24*AS24*4*12 -> 0 | AU24: =AT24*M24 -> 0 | AV24: =AT24*K24 -> 0 | AW24: =Z24*J24*AS24*4*12 -> 0 | AX24: =AT24*E24 -> 0 | AY24: =AX24*F24 -> 0 | AZ24: =AT24*D24*H24 -> 0 | BA24: =Z24*I24*AS24*4*12 -> 0 | BB24: =AR24*AS24*4*12 -> 0 | BC24: =BB24*G24 -> 0 | BD24: =BB24*$BD$17 -> 0 | BE24: =BB24*$BE$17 -> 0 | BG24: =AC24+AE24+AG24+AI24+AK24+AM24 -> 0 | BH24: =AE24+AG24+AI24+AK24+AM24+AO24 -> 0 | BJ24: =BG24*BI24*4*12 -> 0 | BK24: =BJ24*AB24 -> 0 | BL24: =BJ24*K24 -> 0 | BM24: =BI24*AO24*4*12*J24 -> 0 | BN24: =BJ24*E24 -> 0 | BO24: =BN24*F24 -> 0 | BP24: =BJ24*D24*H24 -> 0 | BQ24: =BI24*AO24*I24*4*12 -> 0 | BR24: =BH24*BI24*4*12 -> 0 | BS24: =BR24*G24 -> 0
AQ25: =SUM(AQ18:AQ24) -> 22 | AT25: =SUM(AT18:AT24) -> 7392 | AU25: =SUM(AU18:AU24) -> 66528000 | AV25: =SUM(AV18:AV24) -> 11088000 | AW25: =SUM(AW18:AW24) -> 403200 | AX25: =SUM(AX18:AX24) -> 6652800 | AY25: =SUM(AY18:AY24) -> 19958400 | AZ25: =SUM(AZ18:AZ24) -> 1293600 | BA25: =SUM(BA18:BA24) -> 4182528 | ... BE25: =SUM(BE18:BE24) -> 81984000 | BG25: =SUM(BG18:BG24) -> 12 | BJ25: =SUM(BJ18:BJ24) -> 4032 | BK25: =SUM(BK18:BK24) -> 40320000 | BL25: =SUM(BL18:BL24) -> 6048000 | BM25: =SUM(BM18:BM24) -> 201600 | BN25: =SUM(BN18:BN24) -> 3628800 | BO25: =SUM(BO18:BO24) -> 10886400 | BP25: =SUM(BP18:BP24) -> 705600 | BQ25: =SUM(BQ18:BQ24) -> 2091264 | ... BS25: =SUM(BS18:BS24) -> 1226568
AU26: =AV25+AW25+AY25+AZ25+BA25+BC25 -> 41024928 | BE26: =BD25+BE25+AU25 -> 271488000 | BJ26: =BJ25+AT25 -> 11424 | BK26: total maint | BL26: =BL25+AV25 -> 17136000 | BN26: total fuel | BO26: =BO25+AY25 -> 30844800 | BP26: TOT. AERO. | BQ26: =BQ25+BP25+BM25+BS25+BC25+BA25+AZ25+AW25 -> 14203560
M30: FRESH | AB30: GSA | AQ30: FRESH | BG30: FRESH
E31: Fuel b. | K31: mtt x | M31: IND CHR. F24 | N31: l1 | P31: l2 | R31: l3 | T31: l4 | V31: l5 | X31: l6 | Z31: LDG | AB31: IND CHR. GSA | AC31: l1 | AE31: l2 | AG31: l3 | AI31: l4 | AK31: l5 | AM31: l6 | AQ31: total dia | AS31: TOTAL | BD31: Cargo buy | BE31: profit | BG31: total dia | BI31: TOTAL
C32: MTOW | D32: M/HORA | E32: GLS | F32: $ | G32: HAND. | H32: OVER/F | I32: LDG FEES | J32: T/A FEES | K32: HORA | N32: F/H | O32: Cargo | P32: F/H | Q32: Cargo | R32: F/H | S32: Cargo | T32: F/H | U32: Cargo | V32: F/H | W32: Cargo | X32: F/H | Y32: Cargo | AC32: F/H | AD32: Cargo | AE32: F/H | AF32: Cargo | AG32: F/H | AH32: Cargo | AI32: F/H | AJ32: Cargo | AK32: F/H | AL32: Cargo | AM32: F/H | AN32: Cargo | AO32: LDG | AQ32: F/H | AR32: Cargo | AS32: x/W | AT32: F/H | AU32: air log $ | AV32: Maint. | AW32: T/A | AX32: FUEL GLS | AY32: FUEL $ | AZ32: O/FLIGHT | BA32: LDG FEES | BB32: Cargo (Kg) | BC32: Handling | BD32: 3 | BE32: 2 | BG32: F/H | BH32: Cargo | BI32: x/W | BJ32: F/H | BK32: air log $ | BL32: Maint. | BM32: T/A | BN32: FUEL GLS | BO32: FUEL $ | BP32: O/FLIGHT | BQ32: LDG FEES | BR32: Cargo (Kg) | BS32: Handling
A33: 1 | B33: A321 | C33: 77800 | D33: 500 | E33: 900 | F33: 3 | G33: 0.1 | H33: 0.35 | I33: =C33*0.02 -> 1556 | J33: 150 | K33: 1500 | M33: 9000 | N33: 2.5 | O33: 24500 | P33: 2.5 | R33: 3 | S33: 24500 | T33: 3 | U33: 12000 | Z33: 4 | AB33: 10000 | AC33: 3 | AD33: 24500 | AO33: 1 | AQ33: =N33+P33+R33+T33+V33+X33 -> 11 | AR33: =O33+Q33+S33+U33+W33+Y33 -> 61000 | AS33: 6 | AT33: =AQ33*AS33*4*12 -> 3168 | AU33: =AT33*M33 -> 28512000 | AV33: =AT33*K33 -> 4752000 | AW33: =Z33*J33*AS33*4*12 -> 172800 | AX33: =AT33*E33 -> 2851200 | AY33: =AX33*F33 -> 8553600 | AZ33: =AT33*D33*H33 -> 554400 | BA33: =Z33*I33*AS33*4*12 -> 1792512 | BB33: =AR33*AS33*4*12 -> 17568000 | BC33: =BB33*G33 -> 1756800 | BD33: =BB33*$BD$32 -> 52704000 | BE33: =BB33*$BE$32 -> 35136000 | BG33: =AC33+AE33+AG33+AI33+AK33+AM33 -> 3 | BH33: =AD33+AF33+AH33+AJ33+AL33+AN33 -> 24500 | BI33: 7 | BJ33: =BG33*BI33*4*12 -> 1008 | BK33: =BJ33*AB33 -> 10080000 | BL33: =BJ33*K33 -> 1512000 | BM33: =BI33*AO33*4*12*J33 -> 50400 | BN33: =BJ33*E33 -> 907200 | BO33: =BN33*F33 -> 2721600 | BP33: =BJ33*D33*H33 -> 176400 | BQ33: =BI33*AO33*I33*4*12 -> 522816 | BR33: =BH33*BI33*4*12 -> 8232000 | BS33: =BR33*G33 -> 823200
A34: 1 | B34: A321 | C34: 77800 | D34: 500 | E34: 900 | F34: 3 | G34: 0.1 | H34: 0.35 | I34: =C34*0.02 -> 1556 | J34: 150 | K34: 1500 | M34: 9000 | N34: 2.5 | O34: 24500 | P34: 2.5 | R34: 3 | S34: 24500 | T34: 3 | U34: 12000 | Z34: 4 | AB34: 10000 | AC34: 3 | AD34: 24500 | AO34: 1 | AQ34: =N34+P34+R34+T34+V34+X34 -> 11 | AR34: =O34+Q34+S34+U34+W34+Y34 -> 61000 | AS34: 6 | AT34: =AQ34*AS34*4*12 -> 3168 | AU34: =AT34*M34 -> 28512000 | AV34: =AT34*K34 -> 4752000 | AW34: =Z34*J34*AS34*4*12 -> 172800 | AX34: =AT34*E34 -> 2851200 | AY34: =AX34*F34 -> 8553600 | AZ34: =AT34*D34*H34 -> 554400 | BA34: =Z34*I34*AS34*4*12 -> 1792512 | BB34: =AR34*AS34*4*12 -> 17568000 | BC34: =BB34*G34 -> 1756800 | BD34: =BB34*$BD$32 -> 52704000 | BE34: =BB34*$BE$32 -> 35136000 | BG34: =AC34+AE34+AG34+AI34+AK34+AM34 -> 3 | BH34: =AD34+AF34+AH34+AJ34+AL34+AN34 -> 24500 | BI34: 7 | BJ34: =BG34*BI34*4*12 -> 1008 | BK34: =BJ34*AB34 -> 10080000 | BL34: =BJ34*K34 -> 1512000 | BM34: =BI34*AO34*4*12*J34 -> 50400 | BN34: =BJ34*E34 -> 907200 | BO34: =BN34*F34 -> 2721600 | BP34: =BJ34*D34*H34 -> 176400 | BQ34: =BI34*AO34*I34*4*12 -> 522816 | BR34: =BH34*BI34*4*12 -> 8232000 | BS34: =BR34*G34 -> 823200
A35: 2 | B35: A321 | C35: 77800 | D35: 500 | E35: 900 | F35: 3 | G35: 0.1 | H35: 0.35 | I35: =C35*0.02 -> 1556 | J35: 150 | K35: 1500 | M35: 9000 | N35: 2.5 | O35: 24500 | P35: 2.5 | R35: 3 | S35: 24500 | T35: 3 | U35: 12000 | Z35: 4 | AB35: 10000 | AC35: 3 | AD35: 24500 | AO35: 1 | AQ35: =N35+P35+R35+T35+V35+X35 -> 11 | AR35: =O35+Q35+S35+U35+W35+Y35 -> 61000 | AS35: 5 | AT35: =AQ35*AS35*4*12 -> 2640 | AU35: =AT35*M35 -> 23760000 | AV35: =AT35*K35 -> 3960000 | AW35: =Z35*J35*AS35*4*12 -> 144000 | AX35: =AT35*E35 -> 2376000 | AY35: =AX35*F35 -> 7128000 | AZ35: =AT35*D35*H35 -> 462000 | BA35: =Z35*I35*AS35*4*12 -> 1493760 | BB35: =AR35*AS35*4*12 -> 14640000 | BC35: =BB35*G35 -> 1464000 | BD35: =BB35*$BD$32 -> 43920000 | BE35: =BB35*$BE$32 -> 29280000 | BG35: =AC35+AE35+AG35+AI35+AK35+AM35 -> 3 | BH35: =AE35+AG35+AI35+AK35+AM35+AO35 -> 1 | BI35: 7 | BJ35: =BG35*BI35*4*12 -> 1008 | BK35: =BJ35*AB35 -> 10080000 | BL35: =BJ35*K35 -> 1512000 | BM35: =BI35*AO35*4*12*J35 -> 50400 | BN35: =BJ35*E35 -> 907200 | BO35: =BN35*F35 -> 2721600 | BP35: =BJ35*D35*H35 -> 176400 | BQ35: =BI35*AO35*I35*4*12 -> 522816 | BR35: =BH35*BI35*4*12 -> 336 | BS35: =BR35*G35 -> 33.6
A36: 3 | B36: A321 | C36: 77800 | D36: 500 | E36: 900 | F36: 3 | G36: 0.1 | H36: 0.35 | I36: =C36*0.02 -> 1556 | J36: 150 | K36: 1500 | M36: 9000 | AB36: 10000 | AQ36: =N36+P36+R36+T36+V36+X36 -> 0 | AR36: =O36+Q36+S36+U36+W36+Y36 -> 0 | AT36: =AQ36*AS36*4*12 -> 0 | AU36: =AT36*M36 -> 0 | AV36: =AT36*K36 -> 0 | AW36: =Z36*J36*AS36*4*12 -> 0 | AX36: =AT36*E36 -> 0 | AY36: =AX36*F36 -> 0 | AZ36: =AT36*D36*H36 -> 0 | BA36: =Z36*I36*AS36*4*12 -> 0 | BB36: =AR36*AS36*4*12 -> 0 | BC36: =BB36*G36 -> 0 | BD36: =BB36*$BD$32 -> 0 | BE36: =BB36*$BE$32 -> 0 | BG36: =AC36+AE36+AG36+AI36+AK36+AM36 -> 0 | BH36: =AE36+AG36+AI36+AK36+AM36+AO36 -> 0 | BJ36: =BG36*BI36*4*12 -> 0 | BK36: =BJ36*AB36 -> 0 | BL36: =BJ36*K36 -> 0 | BM36: =BI36*AO36*4*12*J36 -> 0 | BN36: =BJ36*E36 -> 0 | BO36: =BN36*F36 -> 0 | BP36: =BJ36*D36*H36 -> 0 | BQ36: =BI36*AO36*I36*4*12 -> 0 | BR36: =BH36*BI36*4*12 -> 0 | BS36: =BR36*G36 -> 0
A37: 4 | B37: A321 | C37: 77800 | D37: 500 | E37: 900 | F37: 3 | G37: 0.1 | H37: 0.35 | I37: =C37*0.02 -> 1556 | J37: 150 | K37: 1500 | M37: 9000 | AB37: 10000 | AQ37: =N37+P37+R37+T37+V37+X37 -> 0 | AR37: =O37+Q37+S37+U37+W37+Y37 -> 0 | AT37: =AQ37*AS37*4*12 -> 0 | AU37: =AT37*M37 -> 0 | AV37: =AT37*K37 -> 0 | AW37: =Z37*J37*AS37*4*12 -> 0 | AX37: =AT37*E37 -> 0 | AY37: =AX37*F37 -> 0 | AZ37: =AT37*D37*H37 -> 0 | BA37: =Z37*I37*AS37*4*12 -> 0 | BB37: =AR37*AS37*4*12 -> 0 | BC37: =BB37*G37 -> 0 | BD37: =BB37*$BD$32 -> 0 | BE37: =BB37*$BE$32 -> 0 | BG37: =AC37+AE37+AG37+AI37+AK37+AM37 -> 0 | BH37: =AE37+AG37+AI37+AK37+AM37+AO37 -> 0 | BJ37: =BG37*BI37*4*12 -> 0 | BK37: =BJ37*AB37 -> 0 | BL37: =BJ37*K37 -> 0 | BM37: =BI37*AO37*4*12*J37 -> 0 | BN37: =BJ37*E37 -> 0 | BO37: =BN37*F37 -> 0 | BP37: =BJ37*D37*H37 -> 0 | BQ37: =BI37*AO37*I37*4*12 -> 0 | BR37: =BH37*BI37*4*12 -> 0 | BS37: =BR37*G37 -> 0
A38: 3 | B38: B777 | C38: 260800 | D38: 500 | E38: 1800 | F38: 3 | G38: 0.1 | H38: 0.35 | I38: =C38*0.02 -> 5216 | J38: 350 | K38: 5500 | M38: 18000 | N38: 13 | O38: 102000 | Z38: 1 | AB38: 20000 | AQ38: =N38+P38+R38+T38+V38+X38 -> 13 | AR38: =O38+Q38+S38+U38+W38+Y38 -> 102000 | AS38: 5 | AT38: =AQ38*AS38*4*12 -> 3120 | AU38: =AT38*M38 -> 56160000 | AV38: =AT38*K38 -> 17160000 | AW38: =Z38*J38*AS38*4*12 -> 84000 | AX38: =AT38*E38 -> 5616000 | AY38: =AX38*F38 -> 16848000 | AZ38: =AT38*D38*H38 -> 546000 | BA38: =Z38*I38*AS38*4*12 -> 1251840 | BB38: =AR38*AS38*4*12 -> 24480000 | BC38: =BB38*G38 -> 2448000 | BD38: =BB38*$BD$32 -> 73440000 | BE38: =BB38*$BE$32 -> 48960000 | BG38: =AC38+AE38+AG38+AI38+AK38+AM38 -> 0 | BH38: =AE38+AG38+AI38+AK38+AM38+AO38 -> 0 | BJ38: =BG38*BI38*4*12 -> 0 | BK38: =BJ38*AB38 -> 0 | BL38: =BJ38*K38 -> 0 | BM38: =BI38*AO38*4*12*J38 -> 0 | BN38: =BJ38*E38 -> 0 | BO38: =BN38*F38 -> 0 | BP38: =BJ38*D38*H38 -> 0 | BQ38: =BI38*AO38*I38*4*12 -> 0 | BR38: =BH38*BI38*4*12 -> 0 | BS38: =BR38*G38 -> 0
A39: 4 | B39: B777 | C39: 260800 | D39: 500 | E39: 1800 | F39: 3 | G39: 0.1 | H39: 0.35 | I39: =C39*0.02 -> 5216 | J39: 350 | K39: 5500 | M39: 18000 | AB39: 20000 | AQ39: =N39+P39+R39+T39+V39+X39 -> 0 | AR39: =O39+Q39+S39+U39+W39+Y39 -> 0 | AT39: =AQ39*AS39*4*12 -> 0 | AU39: =AT39*M39 -> 0 | AV39: =AT39*K39 -> 0 | AW39: =Z39*J39*AS39*4*12 -> 0 | AX39: =AT39*E39 -> 0 | AY39: =AX39*F39 -> 0 | AZ39: =AT39*D39*H39 -> 0 | BA39: =Z39*I39*AS39*4*12 -> 0 | BB39: =AR39*AS39*4*12 -> 0 | BC39: =BB39*G39 -> 0 | BD39: =BB39*$BD$32 -> 0 | BE39: =BB39*$BE$32 -> 0 | BG39: =AC39+AE39+AG39+AI39+AK39+AM39 -> 0 | BH39: =AE39+AG39+AI39+AK39+AM39+AO39 -> 0 | BJ39: =BG39*BI39*4*12 -> 0 | BK39: =BJ39*AB39 -> 0 | BL39: =BJ39*K39 -> 0 | BM39: =BI39*AO39*4*12*J39 -> 0 | BN39: =BJ39*E39 -> 0 | BO39: =BN39*F39 -> 0 | BP39: =BJ39*D39*H39 -> 0 | BQ39: =BI39*AO39*I39*4*12 -> 0 | BR39: =BH39*BI39*4*12 -> 0 | BS39: =BR39*G39 -> 0
AQ40: =SUM(AQ33:AQ37) -> 33 | AT40: =SUM(AT33:AT39) -> 12096 | AU40: =SUM(AU33:AU37) -> 80784000 | AV40: =SUM(AV33:AV39) -> 30624000 | AW40: =SUM(AW33:AW39) -> 573600 | AX40: =SUM(AX33:AX39) -> 13694400 | AY40: =SUM(AY33:AY39) -> 41083200 | AZ40: =SUM(AZ33:AZ39) -> 2116800 | BA40: =SUM(BA33:BA39) -> 6330624 | BB40: =SUM(BB33:BB37) -> 49776000 | BC40: =SUM(BC33:BC39) -> 7425600 | BD40: =SUM(BD33:BD37) -> 149328000 | BE40: =SUM(BE33:BE37) -> 99552000 | BG40: =SUM(BG33:BG37) -> 9 | BJ40: =SUM(BJ33:BJ39) -> 3024 | BK40: =SUM(BK33:BK39) -> 30240000 | BL40: =SUM(BL33:BL39) -> 4536000 | BM40: =SUM(BM33:BM39) -> 151200 | BN40: =SUM(BN33:BN39) -> 2721600 | BO40: =SUM(BO33:BO39) -> 8164800 | BP40: =SUM(BP33:BP39) -> 529200 | BQ40: =SUM(BQ33:BQ39) -> 1568448 | ... BS40: =SUM(BS33:BS39) -> 1646433.6
AQ41: =SUM(AQ38:AQ39) -> 13 | AU41: =SUM(AU38:AU39) -> 56160000 | BB41: =SUM(BB38:BB39) -> 24480000 | BD41: =SUM(BD38:BD39) -> 73440000 | BE41: =SUM(BE38:BE39) -> 48960000 | BG41: =SUM(BG38:BG39) -> 0 | BJ41: =BJ40+AT40 -> 15120 | BK41: total maint | BL41: =BL40+AV40 -> 35160000 | BN41: total fuel | BO41: =BO40+AY40 -> 49248000 | BP41: TOT. AERO. | BQ41: =BQ40+BP40+BM40+BS40+BC40+BA40+AZ40+AW40 -> 20341906
AU42: =SUM(AU40:AU41) -> 136944000 | BB42: =SUM(BB40:BB41) -> 74256000 | BD42: =SUM(BD40:BD41) -> 222768000 | BE42: =SUM(BE40:BE41) -> 148512000
BD43: =AU40+BD40+BE40 -> 329664000
BD44: =AU41+BD41+BE41 -> 178560000 | BE44: =BD42+BE42+AU42 -> 508224000
M45: FRESH | AB45: GSA | AQ45: FRESH | BG45: FRESH
...

Sheet Income FRESH24
A1: FRESH 24
A2: Statements of Operations (Unaudited)
B3: YEAR 1 | C3: YEAR 2 | D3: YEAR 3 | E3: YEAR 4 | F3: YEAR 5
A4: Revenues:
A5: Direct Product Sales Americas | B5: =ANALYSIS!BE12 -> 164592000 | C5: =ANALYSIS!BE26 -> 271488000 | D5: =ANALYSIS!BD43 -> 329664000 | E5: =ANALYSIS!BD58 -> 465408000 | F5: =ANALYSIS!BD75 -> 620544000
A6: Direct Product Sales Eurasia | D6: =ANALYSIS!BD44 -> 178560000 | E6: =ANALYSIS!BD59 -> 321408000 | F6: =ANALYSIS!BD76 -> 357120000
A7: OtherServices
A9: Total revenue | B9: =SUM(B5:B8) -> 164592000 | C9: =SUM(C5:C8) -> 271488000 | D9: =SUM(D5:D8) -> 508224000 | E9: =SUM(E5:E8) -> 786816000 | F9: =SUM(F5:F8) -> 977664000
A11: Operating expenses:
A12: Air logistic | B12: =ANALYSIS!AU11 -> 41472000 | C12: =ANALYSIS!AU25 -> 66528000 | D12: =ANALYSIS!AU42 -> 136944000 | E12: =ANALYSIS!AU57 -> 215136000 | F12: =ANALYSIS!AU74 -> 264384000
A13: Sales & marketing | B13: 1200000 | C13: 1400000 | D13: 2200000 | E13: 3000000 | F13: 4000000
A14: products | B14: =ANALYSIS!BD11 -> 73872000 | C14: =ANALYSIS!BD25 -> 122976000 | D14: =ANALYSIS!BD42 -> 222768000 | E14: =ANALYSIS!BD57 -> 343008000 | F14: =ANALYSIS!BD74 -> 427968000
A15: Other expenses* | B15: 2200000 | C15: 2500000 | D15: 2750000 | E15: 3000000 | F15: 6000000
A16: Total operating expenses | B16: =SUM(B12:B15) -> 118744000 | C16: =SUM(C12:C15) -> 193404000 | D16: =SUM(D12:D15) -> 364662000 | E16: =SUM(E12:E15) -> 564144000 | F16: =SUM(F12:F15) -> 702352000
A18: Operating income/(loss) | B18: =B9-B16 -> 45848000 | C18: =C9-C16 -> 78084000 | D18: =D9-D16 -> 143562000 | E18: =E9-E16 -> 222672000 | F18: =F9-F16 -> 275312000
A19: Operating margin | B19: =B18/B9 -> 0.27855546 | C19: =C18/C9 -> 0.28761492 | D19: =D18/D9 -> 0.28247781 | E19: =E18/E9 -> 0.2830039 | F19: =F18/F9 -> 0.28160186
A20: Non-operating expense (income):
A21: Admin payroll | B21: 1800000 | C21: 2000000 | D21: 2800000 | E21: 3500000 | F21: 4000000
A22: Admin expenses | B22: 2500000 | C22: 2750000 | D22: 4250000 | E22: 4750000 | F22: 5250000
A23: Total non-operating expenses | B23: =SUM(B21:B22) -> 4300000 | C23: =SUM(C21:C22) -> 4750000 | D23: =SUM(D21:D22) -> 7050000 | E23: =SUM(E21:E22) -> 8250000 | F23: =SUM(F21:F22) -> 9250000
A25: EBITDA | B25: =B18-B23 -> 41548000 | C25: =C18-C23 -> 73334000 | D25: =D18-D23 -> 136512000 | E25: =E18-E23 -> 214422000 | F25: =F18-F23 -> 266062000
A26: EBITDA margin | B26: =B25/B9 -> 0.25243025 | C26: =C25/C9 -> 0.27011875 | D26: =D25/D9 -> 0.26860597 | E26: =E25/E9 -> 0.27251861 | F26: =F25/F9 -> 0.27214053
A27: Loan interest | B27: ='loan 1 FRESH24'!E18*-1 -> 2574728.1 | C27: ='loan 1 FRESH24'!E30*-1 -> 2420901.4 | D27: ='loan 1 FRESH24'!E42*-1 -> 2247565.6 | E27: ='loan 1 FRESH24'!E54*-1 -> 2052246.5 | F27: ='loan 1 FRESH24'!E66*-1 -> 1832156
A28: Depreciation | B28: 450000 | C28: 475000 | D28: 650000 | E28: 850000 | F28: 1000000
A29: Tax provision (25%) | B29: =B25*variables!$C$8 -> 10387000 | C29: =C25*variables!$C$8 -> 18333500 | D29: =D25*variables!$C$8 -> 34128000 | E29: =E25*variables!$C$8 -> 53605500 | F29: =F25*variables!$C$8 -> 66515500
A30: Net income/(loss) | B30: =B25-B29-B28-B27 -> 28136272 | C30: =C25-C29-C28-C27 -> 52104599 | D30: =D25-D29-D28-D27 -> 99486434 | E30: =E25-E29-E28-E27 -> 1.5791425e+08 | F30: =F25-F29-F28-F27 -> 1.9671434e+08
A31: Net income margin | B31: =B30/B9 -> 0.17094556 | C31: =C30/C9 -> 0.19192229 | D31: =D30/D9 -> 0.19575312 | E31: =E30/E9 -> 0.20070036 | F31: =F30/F9 -> 0.20120854

Sheet Cash flow FRESH24
A1: FRESH24 cash flow operations
B2: YEAR 1 | C2: YEAR 2 | D2: YEAR 3 | E2: YEAR 4 | F2: YEAR 5
A3: Beginning cash balance | C3: =B44 -> 29873367 | D3: =C44 -> 77586234 | E3: =D44 -> 1.754751e+08 | F3: =E44 -> 3.2768711e+08
A5: Cash flow from operating activities
A7: Net Income (from Income Statement) | B7: ='Income FRESH24'!B30 -> 28136272 | C7: ='Income FRESH24'!C30 -> 52104599 | D7: ='Income FRESH24'!D30 -> 99486434 | E7: ='Income FRESH24'!E30 -> 1.5791425e+08 | F7: ='Income FRESH24'!F30 -> 1.9671434e+08
A9: Adjustments for Non-Cash Items
A11: Depreciation & Amortization | B11: ='Income FRESH24'!B28 -> 450000 | C11: ='Income FRESH24'!C28 -> 475000 | D11: ='Income FRESH24'!D28 -> 650000 | E11: ='Income FRESH24'!E28 -> 850000 | F11: ='Income FRESH24'!F28 -> 1000000
A12: Provisions (if applicable)
A13: Losses / (-) Gains on Asset Disposal
A15: Adjustments for Working Capital Changes
A17: Increase in Accounts Receivable
A18: Decrease in Accounts Receivable
A19: Increase in Inventory (if applicable)
A20: Decrease in Inventory (if applicable)
A21: Increase in Accounts Payable
A22: Decrease in Accounts Payable
A23: Changes in Other Current Assets
A24: Changes in Other Current Liabilities
A26: Net Cash from Operating Activities | B26: =B7+B11+B12+B13-B17+B18-B19+B20+B21-B22-B23+B24 -> 28586272 | C26: =C3+C7+C11+C12+C13-C17+C18-C19+C20+C21-C22-C23+C24 -> 82452966 | D26: =D3+D7+D11+D12+D13-D17+D18-D19+D20+D21-D22-D23+D24 -> 1.7772267e+08 | E26: =E3+E7+E11+E12+E13-E17+E18-E19+E20+E21-E22-E23+E24 -> 3.3423936e+08 | F26: =F3+F7+F11+F12+F13-F17+F18-F19+F20+F21-F22-F23+F24 -> 5.2540145e+08
A28: Cash flow from investing activities
A30: Capital Expenditures (CapEx) | B30: -19500000 | C30: -3500000 | E30: -4500000
A32: Net Cash Flow from Investing Activities | B32: =B30 -> -19500000 | C32: =C30 -> -3500000 | D32: =D30 -> 0 | E32: =E30 -> -4500000 | F32: =F30 -> 0
A34: Cash flow from Financing Activities
A36: Debt Issuance | B36: 22000000
A37: Debt Repayments (Principal) | B37: ='loan 1 FRESH24'!F18*-1 -> -1212905 | C37: ='loan 1 FRESH24'!F30*-1 -> -1366731.7 | D37: ='loan 1 FRESH24'!E42 -> -2247565.6 | E37: ='loan 1 FRESH24'!E54 -> -2052246.5 | F37: ='loan 1 FRESH24'!E66 -> -1832156
A38: Interest Payments
A39: Equity Contributions
A40: Dividends Paid (-)
A42: Net Cash Flow from Financing Activities | B42: =SUM(B36:B41) -> 20787095 | C42: =SUM(C36:C41) -> -1366731.7 | D42: =SUM(D36:D41) -> -2247565.6 | E42: =SUM(E36:E41) -> -2052246.5 | F42: =SUM(F36:F41) -> -1832156
A44: Net Cash Flow | B44: =B26+B32+B42 -> 29873367 | C44: =C26+C32+C42 -> 77586234 | D44: =D26+D32+D42 -> 1.754751e+08 | E44: =E26+E32+E42 -> 3.2768711e+08 | F44: =F26+F32+F42 -> 5.235693e+08

Sheet loan 1 FRESH24
A1: loan amount | B1: 22000000
A2: Loan term | B2: 120
A3: Annual rate | B3: 0.12
A4: Monthly payment | B4: =PMT(B3/12,B2,-(B1)) -> 315636.09
A6: 0 | B6: payment | C6: interest | D6: remaining
A7: 1 | B7: =$B$4 -> 315636.09 | C7: =IPMT($B$3/12,A7,$B$2,($B$1)) -> -220000 | D7: =B7+C7 -> 95636.086
A8: 2 | B8: =$B$4 -> 315636.09 | C8: =IPMT($B$3/12,A8,$B$2,($B$1)) -> -219043.64 | D8: =B8+C8 -> 96592.447
A9: 3 | B9: =$B$4 -> 315636.09 | C9: =IPMT($B$3/12,A9,$B$2,($B$1)) -> -218077.71 | D9: =B9+C9 -> 97558.372
A10: 4 | B10: =$B$4 -> 315636.09 | C10: =IPMT($B$3/12,A10,$B$2,($B$1)) -> -217102.13 | D10: =B10+C10 -> 98533.956
A11: 5 | B11: =$B$4 -> 315636.09 | C11: =IPMT($B$3/12,A11,$B$2,($B$1)) -> -216116.79 | D11: =B11+C11 -> 99519.295
A12: 6 | B12: =$B$4 -> 315636.09 | C12: =IPMT($B$3/12,A12,$B$2,($B$1)) -> -215121.6 | D12: =B12+C12 -> 100514.49
A13: 7 | B13: =$B$4 -> 315636.09 | C13: =IPMT($B$3/12,A13,$B$2,($B$1)) -> -214116.45 | D13: =B13+C13 -> 101519.63
A14: 8 | B14: =$B$4 -> 315636.09 | C14: =IPMT($B$3/12,A14,$B$2,($B$1)) -> -213101.26 | D14: =B14+C14 -> 102534.83
A15: 9 | B15: =$B$4 -> 315636.09 | C15: =IPMT($B$3/12,A15,$B$2,($B$1)) -> -212075.91 | D15: =B15+C15 -> 103560.18
A16: 10 | B16: =$B$4 -> 315636.09 | C16: =IPMT($B$3/12,A16,$B$2,($B$1)) -> -211040.31 | D16: =B16+C16 -> 104595.78
A17: 11 | B17: =$B$4 -> 315636.09 | C17: =IPMT($B$3/12,A17,$B$2,($B$1)) -> -209994.35 | D17: =B17+C17 -> 105641.74
A18: 12 | B18: =$B$4 -> 315636.09 | C18: =IPMT($B$3/12,A18,$B$2,($B$1)) -> -208937.93 | D18: =B18+C18 -> 106698.15 | E18: =SUM(C7:C18) -> -2574728.1 | F18: =SUM(D7:D18) -> 1212905 | G18: =SUM(B7:B18) -> 3787633
A19: 13 | B19: =$B$4 -> 315636.09 | C19: =IPMT($B$3/12,A19,$B$2,($B$1)) -> -207870.95 | D19: =B19+C19 -> 107765.14
A20: 14 | B20: =$B$4 -> 315636.09 | C20: =IPMT($B$3/12,A20,$B$2,($B$1)) -> -206793.3 | D20: =B20+C20 -> 108842.79
A21: 15 | B21: =$B$4 -> 315636.09 | C21: =IPMT($B$3/12,A21,$B$2,($B$1)) -> -205704.87 | D21: =B21+C21 -> 109931.22
A22: 16 | B22: =$B$4 -> 315636.09 | C22: =IPMT($B$3/12,A22,$B$2,($B$1)) -> -204605.56 | D22: =B22+C22 -> 111030.53
A23: 17 | B23: =$B$4 -> 315636.09 | C23: =IPMT($B$3/12,A23,$B$2,($B$1)) -> -203495.25 | D23: =B23+C23 -> 112140.83
A24: 18 | B24: =$B$4 -> 315636.09 | C24: =IPMT($B$3/12,A24,$B$2,($B$1)) -> -202373.85 | D24: =B24+C24 -> 113262.24
A25: 19 | B25: =$B$4 -> 315636.09 | C25: =IPMT($B$3/12,A25,$B$2,($B$1)) -> -201241.22 | D25: =B25+C25 -> 114394.86
A26: 20 | B26: =$B$4 -> 315636.09 | C26: =IPMT($B$3/12,A26,$B$2,($B$1)) -> -200097.27 | D26: =B26+C26 -> 115538.81
A27: 21 | B27: =$B$4 -> 315636.09 | C27: =IPMT($B$3/12,A27,$B$2,($B$1)) -> -198941.89 | D27: =B27+C27 -> 116694.2
A28: 22 | B28: =$B$4 -> 315636.09 | C28: =IPMT($B$3/12,A28,$B$2,($B$1)) -> -197774.94 | D28: =B28+C28 -> 117861.14
A29: 23 | B29: =$B$4 -> 315636.09 | C29: =IPMT($B$3/12,A29,$B$2,($B$1)) -> -196596.33 | D29: =B29+C29 -> 119039.75
A30: 24 | B30: =$B$4 -> 315636.09 | C30: =IPMT($B$3/12,A30,$B$2,($B$1)) -> -195405.94 | D30: =B30+C30 -> 120230.15 | E30: =SUM(C19:C30) -> -2420901.4 | F30: =SUM(D19:D30) -> 1366731.7 | G30: =F30-E30 -> 3787633
A31: 25 | B31: =$B$4 -> 315636.09 | C31: =IPMT($B$3/12,A31,$B$2,($B$1)) -> -194203.63 | D31: =B31+C31 -> 121432.45
A32: 26 | B32: =$B$4 -> 315636.09 | C32: =IPMT($B$3/12,A32,$B$2,($B$1)) -> -192989.31 | D32: =B32+C32 -> 122646.78
A33: 27 | B33: =$B$4 -> 315636.09 | C33: =IPMT($B$3/12,A33,$B$2,($B$1)) -> -191762.84 | D33: =B33+C33 -> 123873.24
A34: 28 | B34: =$B$4 -> 315636.09 | C34: =IPMT($B$3/12,A34,$B$2,($B$1)) -> -190524.11 | D34: =B34+C34 -> 125111.98
A35: 29 | B35: =$B$4 -> 315636.09 | C35: =IPMT($B$3/12,A35,$B$2,($B$1)) -> -189272.99 | D35: =B35+C35 -> 126363.1
A36: 30 | B36: =$B$4 -> 315636.09 | C36: =IPMT($B$3/12,A36,$B$2,($B$1)) -> -188009.36 | D36: =B36+C36 -> 127626.73
A37: 31 | B37: =$B$4 -> 315636.09 | C37: =IPMT($B$3/12,A37,$B$2,($B$1)) -> -186733.09 | D37: =B37+C37 -> 128903
A38: 32 | B38: =$B$4 -> 315636.09 | C38: =IPMT($B$3/12,A38,$B$2,($B$1)) -> -185444.06 | D38: =B38+C38 -> 130192.03
A39: 33 | B39: =$B$4 -> 315636.09 | C39: =IPMT($B$3/12,A39,$B$2,($B$1)) -> -184142.14 | D39: =B39+C39 -> 131493.95
A40: 34 | B40: =$B$4 -> 315636.09 | C40: =IPMT($B$3/12,A40,$B$2,($B$1)) -> -182827.2 | D40: =B40+C40 -> 132808.89
A41: 35 | B41: =$B$4 -> 315636.09 | C41: =IPMT($B$3/12,A41,$B$2,($B$1)) -> -181499.11 | D41: =B41+C41 -> 134136.97
...

Sheet Income MAJESTIC
A1: MAJESTIC AIR CARGO
A2: Statements of Operations (Unaudited)
B3: YEAR 1 | C3: YEAR 2 | D3: YEAR 3 | E3: YEAR 4 | F3: YEAR 5
A4: Revenues:
A5: Indirect Charter Majestic | B5: =ANALYSIS!AU11 -> 41472000 | C5: =ANALYSIS!AU25 -> 66528000 | D5: =ANALYSIS!AU42 -> 136944000 | E5: =ANALYSIS!AU57 -> 215136000 | F5: =ANALYSIS!AU74 -> 264384000
A6: Indirect charter GSA | B6: =ANALYSIS!BK11 -> 20160000 | C6: =ANALYSIS!BK25 -> 40320000 | D6: =ANALYSIS!BK40 -> 30240000 | E6: =ANALYSIS!BK55 -> 77760000 | F6: =ANALYSIS!BK72 -> 77760000
A7: Direct Charter
A9: Total revenue | B9: =SUM(B5:B8) -> 61632000 | C9: =SUM(C5:C8) -> 106848000 | D9: =SUM(D5:D8) -> 167184000 | E9: =SUM(E5:E8) -> 292896000 | F9: =SUM(F5:F8) -> 342144000
A11: Operating expenses:
A12: Fuel | B12: =ANALYSIS!BO12 -> 17884800 | C12: =ANALYSIS!BO26 -> 30844800 | D12: =ANALYSIS!BO41 -> 49248000 | E12: =ANALYSIS!BO56 -> 85536000 | F12: =ANALYSIS!BO73 -> 100310400
A13: Maintenance | B13: =ANALYSIS!BL12 -> 9936000 | C13: =ANALYSIS!BL26 -> 17136000 | D13: =ANALYSIS!BL41 -> 35160000 | E13: =ANALYSIS!BL56 -> 66240000 | F13: =ANALYSIS!BL73 -> 76008000
A14: Aeronautical | B14: =ANALYSIS!BQ26 -> 14203560 | C14: =ANALYSIS!BQ26 -> 14203560 | D14: =ANALYSIS!BQ41 -> 20341906 | E14: =ANALYSIS!BQ56 -> 30673810 | F14: =ANALYSIS!BQ73 -> 37241794
A15: Staff / Crew | B15: 2850000 | C15: 3450000 | D15: 4450000 | E15: 5750000 | F15: 7000000
A16: Lease / Rent | B16: 450000 | C16: 475000 | D16: 525000 | E16: 600000 | F16: 850000
A17: Training | B17: 450000 | C17: 550000 | D17: 650000 | E17: 950000 | F17: 1250000
A18: Insurance | B18: 600000 | C18: 900000 | D18: 1350000 | E18: 2100000 | F18: 2450000
A19: Other | B19: 527000 | C19: 650000 | D19: 850000 | E19: 1575000 | F19: 2575000
A21: Other expenses*
A22: Total operating expenses | B22: =SUM(B12:B21) -> 46901360 | C22: =SUM(C12:C21) -> 68209360 | D22: =SUM(D12:D21) -> 1.1257491e+08 | E22: =SUM(E12:E21) -> 1.9342481e+08 | F22: =SUM(F12:F21) -> 2.2768519e+08
A24: Operating income/(loss) | B24: =B9-B22 -> 14730640 | C24: =C9-C22 -> 38638640 | D24: =D9-D22 -> 54609094 | E24: =E9-E22 -> 99471190 | F24: =F9-F22 -> 1.1445881e+08
A25: Operating margin | B25: =B24/B9 -> 0.23900961 | C25: =C24/C9 -> 0.36162249 | D25: =D24/D9 -> 0.32664067 | E25: =E24/E9 -> 0.33961266 | F25: =F24/F9 -> 0.33453402
A26: Non-operating expense (income):
A27: Admin payroll | B27: 1500000 | C27: 1750000 | D27: 2250000 | E27: 2750000 | F27: 3500000
A28: Admin expenses | B28: 1000000 | C28: 1400000 | D28: 1800000 | E28: 2200000 | F28: 2850000
A29: Total non-operating expenses | B29: =SUM(B27:B28) -> 2500000 | C29: =SUM(C27:C28) -> 3150000 | D29: =SUM(D27:D28) -> 4050000 | E29: =SUM(E27:E28) -> 4950000 | F29: =SUM(F27:F28) -> 6350000
A31: EBITDA | B31: =B24-B29 -> 12230640 | C31: =C24-C29 -> 35488640 | D31: =D24-D29 -> 50559094 | E31: =E24-E29 -> 94521190 | F31: =F24-F29 -> 1.0810881e+08
A32: EBITDA margin | B32: =B31/B9 -> 0.19844626 | C32: =C31/C9 -> 0.33214136 | D32: =D31/D9 -> 0.30241587 | E32: =E31/E9 -> 0.32271247 | F32: =F31/F9 -> 0.31597458
A33: Loan interest | B33: ='loan 1Majestic'!E18*-1 -> 4908200.6 | C33: =('loan 1Majestic'!E30+'loan 1Majestic'!K18)*-1 -> 6792484 | D33: =('loan 1Majestic'!E42+'loan 1Majestic'!K30+'loan 1Majestic'!Q18)*-1 -> 10105260 | E33: =('loan 1Majestic'!E54+'loan 1Majestic'!K42+'loan 1Majestic'!Q30+'loan 1Majestic'!W18)*-1 -> 14005339 | F33: =('loan 1Majestic'!E66+'loan 1Majestic'!K54+'loan 1Majestic'!Q42+'loan 1Majestic'!W30+'loan 1Majestic'!AC18)*-1 -> 14805460
A34: Depreciation | B34: 255000 | C34: 550000 | D34: 750000 | E34: 1000000 | F34: 1250000
A35: Tax provision (25%) | B35: =B31*variables!$C$8 -> 3057660 | C35: =C31*variables!$C$8 -> 8872160 | D35: =D31*variables!$C$8 -> 12639774 | E35: =E31*variables!$C$8 -> 23630298 | F35: =F31*variables!$C$8 -> 27027202
A36: Net income/(loss) | B36: =B31-B35-B34-B33 -> 4009779.4 | C36: =C31-C35-C34-C33 -> 19273996 | D36: =D31-D35-D34-D33 -> 27064060 | E36: =E31-E35-E34-E33 -> 55885554 | F36: =F31-F35-F34-F33 -> 65026144
A37: Net income margin | B37: =B36/B9 -> 0.065060024 | C37: =C36/C9 -> 0.18038705 | D37: =D36/D9 -> 0.16188188 | E37: =E36/E9 -> 0.19080341 | F37: =F36/F9 -> 0.1900549

Sheet Cash flow MAJESTIC
A1: MAJESTIC AIR CARGO cash flow operations
B2: YEAR 1 | C2: YEAR 2 | D2: YEAR 3 | E2: YEAR 4 | F2: YEAR 5
A3: Beginning cash balance | C3: =B44 -> 3234788.7 | D3: =C44 -> 21403757 | E3: =D44 -> 46223773 | F3: =E44 -> 97997340
A5: Cash flow from operating activities
A7: Net Income (from Income Statement) | B7: ='Income MAJESTIC'!B36 -> 4009779.4 | C7: ='Income MAJESTIC'!C36 -> 19273996 | D7: ='Income MAJESTIC'!D36 -> 27064060 | E7: ='Income MAJESTIC'!E36 -> 55885554 | F7: ='Income MAJESTIC'!F36 -> 65026144
A9: Adjustments for Non-Cash Items
A11: Depreciation & Amortization | B11: ='Income MAJESTIC'!B34 -> 255000 | C11: ='Income MAJESTIC'!C34 -> 550000 | D11: ='Income MAJESTIC'!D34 -> 750000 | E11: ='Income MAJESTIC'!E34 -> 1000000 | F11: ='Income MAJESTIC'!F34 -> 1250000
A12: Provisions (if applicable)
A13: Losses / (-) Gains on Asset Disposal
A15: Adjustments for Working Capital Changes
A17: Increase in Accounts Receivable
A18: Decrease in Accounts Receivable
A19: Increase in Inventory (if applicable)
A20: Decrease in Inventory (if applicable)
A21: Increase in Accounts Payable
A22: Decrease in Accounts Payable
A23: Changes in Other Current Assets
A24: Changes in Other Current Liabilities
A26: Net Cash from Operating Activities | B26: =B7+B11+B12+B13-B17+B18-B19+B20+B21-B22-B23+B24 -> 4264779.4 | C26: =C3+C7+C11+C12+C13-C17+C18-C19+C20+C21-C22-C23+C24 -> 23058785 | D26: =D3+D7+D11+D12+D13-D17+D18-D19+D20+D21-D22-D23+D24 -> 49217818 | E26: =E3+E7+E11+E12+E13-E17+E18-E19+E20+E21-E22-E23+E24 -> 1.0310933e+08 | F26: =F3+F7+F11+F12+F13-F17+F18-F19+F20+F21-F22-F23+F24 -> 1.6427348e+08
A28: Cash flow from investing activities
A30: Capital Expenditures (CapEx) | B30: ='loan 1Majestic'!C1*-1 -> -55000000 | C30: ='loan 1Majestic'!I1*-1 -> -25000000 | D30: ='loan 1Majestic'!O1*-1 -> -50000000 | E30: ='loan 1Majestic'!U1*-1 -> -70000000 | F30: ='loan 1Majestic'!AA1*-1 -> -20000000 | H30: =SUM(B30:G30) -> -220000000
A32: Net Cash Flow from Investing Activities | B32: =B30 -> -55000000 | C32: =C30 -> -25000000 | D32: =D30 -> -50000000 | E32: =E30 -> -70000000 | F32: =F30 -> -20000000
A34: Cash flow from Financing Activities
A36: Debt Issuance | B36: ='loan 1Majestic'!C1 -> 55000000 | C36: ='loan 1Majestic'!I1 -> 25000000 | D36: ='loan 1Majestic'!O1 -> 50000000 | E36: ='loan 1Majestic'!U1 -> 70000000 | F36: ='loan 1Majestic'!AA1 -> 20000000
A37: Debt Repayments (Principal) | B37: ='loan 1Majestic'!E19*-1 -> -1029990.7 | C37: =('loan 1Majestic'!E31+'loan 1Majestic'!K19)*-1 -> -1655027.5 | D37: =('loan 1Majestic'!E43+'loan 1Majestic'!K31+'loan 1Majestic'!Q19)*-1 -> -2994044.7 | E37: =('loan 1Majestic'!E55+'loan 1Majestic'!K43+'loan 1Majestic'!Q31+'loan 1Majestic'!W19)*-1 -> -5111987.4 | F37: =('loan 1Majestic'!E67+'loan 1Majestic'!K55+'loan 1Majestic'!Q43+'loan 1Majestic'!W31+'loan 1Majestic'!AC19)*-1 -> -6031300.1
A38: Interest Payments
A39: Equity Contributions
A40: Dividends Paid (-)
A42: Net Cash Flow from Financing Activities | B42: =SUM(B36:B41) -> 53970009 | C42: =SUM(C36:C41) -> 23344973 | D42: =SUM(D36:D41) -> 47005955 | E42: =SUM(E36:E41) -> 64888013 | F42: =SUM(F36:F41) -> 13968700
A44: Net Cash Flow | B44: =B26+B32+B42 -> 3234788.7 | C44: =C26+C32+C42 -> 21403757 | D44: =D26+D32+D42 -> 46223773 | E44: =E26+E32+E42 -> 97997340 | F44: =F26+F32+F42 -> 1.5824218e+08

Sheet loan 1Majestic
B1: loan amount | C1: 55000000 | H1: loan amount | I1: 25000000 | N1: loan amount | O1: 50000000 | T1: loan amount | U1: 70000000 | Z1: loan amount | AA1: 20000000 | AF1: loan amount | AG1: 40000000
B2: Loan term | C2: 240 | H2: Loan term | I2: 240 | N2: Loan term | O2: 240 | T2: Loan term | U2: 240 | Z2: Loan term | AA2: 240 | AF2: Loan term | AG2: 96
B3: Annual rate | C3: 0.09 | H3: Annual rate | I3: 0.08 | N3: Annual rate | O3: 0.07 | T3: Annual rate | U3: 0.06 | Z3: Annual rate | AA3: 0.06 | AF3: Annual rate | AG3: 0.09
B4: Monthly payment | C4: =PMT(C3/12,C2,-(C1)) -> 494849.28 | H4: Monthly payment | I4: =PMT(I3/12,I2,-(I1)) -> 209110.02 | N4: Monthly payment | O4: =PMT(O3/12,O2,-(O1)) -> 387649.47 | T4: Monthly payment | U4: =PMT(U3/12,U2,-(U1)) -> 501501.74 | Z4: Monthly payment | AA4: =PMT(AA3/12,AA2,-(AA1)) -> 143286.21 | AF4: Monthly payment | AG4: =PMT(AG3/12,AG2,-(AG1)) -> 586008.13
A6: 0 | B6: payment | C6: interest | D6: remaining | G6: 0 | H6: payment | I6: interest | J6: remaining | M6: 0 | N6: payment | O6: interest | P6: remaining | S6: 0 | T6: payment | U6: interest | V6: remaining | Y6: 0 | Z6: payment | AA6: interest | AB6: remaining | AE6: 0 | AF6: payment | AG6: interest | AH6: remaining
A7: 1 | B7: =$C$4 -> 494849.28 | C7: =IPMT($C$3/12,A7,$C$2,($C$1)) -> -412500 | D7: =B7+C7 -> 82349.276 | G7: 1 | H7: =$I$4 -> 209110.02 | I7: =IPMT($I$3/12,G7,$I$2,($I$1)) -> -166666.67 | J7: =H7+I7 -> 42443.351 | M7: 1 | N7: =$O$4 -> 387649.47 | O7: =IPMT($O$3/12,M7,$O$2,($O$1)) -> -291666.67 | P7: =N7+O7 -> 95982.801 | S7: 1 | T7: =$U$4 -> 501501.74 | U7: =IPMT($U$3/12,S7,$U$2,($U$1)) -> -350000 | V7: =T7+U7 -> 151501.74 | Y7: 1 | Z7: =$AA$4 -> 143286.21 | AA7: =IPMT($AA$3/12,Y7,$AA$2,($AA$1)) -> -100000 | AB7: =Z7+AA7 -> 43286.212 | AE7: 1 | AF7: =$AG$4 -> 586008.13 | AG7: =IPMT($AG$3/12,AE7,$AG$2,($AG$1)) -> -300000 | AH7: =AF7+AG7 -> 286008.13
A8: 2 | B8: =$C$4 -> 494849.28 | C8: =IPMT($C$3/12,A8,$C$2,($C$1)) -> -411882.38 | D8: =B8+C8 -> 82966.895 | G8: 2 | H8: =$I$4 -> 209110.02 | I8: =IPMT($I$3/12,G8,$I$2,($I$1)) -> -166383.71 | J8: =H8+I8 -> 42726.306 | M8: 2 | N8: =$O$4 -> 387649.47 | O8: =IPMT($O$3/12,G8,$O$2,($O$1)) -> -291106.77 | P8: =N8+O8 -> 96542.701 | S8: 2 | T8: =$U$4 -> 501501.74 | U8: =IPMT($U$3/12,S8,$U$2,($U$1)) -> -349242.49 | V8: =T8+U8 -> 152259.25 | Y8: 2 | Z8: =$AA$4 -> 143286.21 | AA8: =IPMT($AA$3/12,Y8,$AA$2,($AA$1)) -> -99783.569 | AB8: =Z8+AA8 -> 43502.643 | AE8: 2 | AF8: =$AG$4 -> 586008.13 | AG8: =IPMT($AG$3/12,AE8,$AG$2,($AG$1)) -> -297854.94 | AH8: =AF8+AG8 -> 288153.19
A9: 3 | B9: =$C$4 -> 494849.28 | C9: =IPMT($C$3/12,A9,$C$2,($C$1)) -> -411260.13 | D9: =B9+C9 -> 83589.147 | G9: 3 | H9: =$I$4 -> 209110.02 | I9: =IPMT($I$3/12,G9,$I$2,($I$1)) -> -166098.87 | J9: =H9+I9 -> 43011.148 | M9: 3 | N9: =$O$4 -> 387649.47 | O9: =IPMT($O$3/12,G9,$O$2,($O$1)) -> -290543.6 | P9: =N9+O9 -> 97105.867 | S9: 3 | T9: =$U$4 -> 501501.74 | U9: =IPMT($U$3/12,S9,$U$2,($U$1)) -> -348481.2 | V9: =T9+U9 -> 153020.55 | Y9: 3 | Z9: =$AA$4 -> 143286.21 | AA9: =IPMT($AA$3/12,Y9,$AA$2,($AA$1)) -> -99566.056 | AB9: =Z9+AA9 -> 43720.156 | AE9: 3 | AF9: =$AG$4 -> 586008.13 | AG9: =IPMT($AG$3/12,AE9,$AG$2,($AG$1)) -> -295693.79 | AH9: =AF9+AG9 -> 290314.34
A10: 4 | B10: =$C$4 -> 494849.28 | C10: =IPMT($C$3/12,A10,$C$2,($C$1)) -> -410633.21 | D10: =B10+C10 -> 84216.066 | G10: 4 | H10: =$I$4 -> 209110.02 | I10: =IPMT($I$3/12,G10,$I$2,($I$1)) -> -165812.13 | J10: =H10+I10 -> 43297.889 | M10: 4 | N10: =$O$4 -> 387649.47 | O10: =IPMT($O$3/12,G10,$O$2,($O$1)) -> -289977.15 | P10: =N10+O10 -> 97672.317 | S10: 4 | T10: =$U$4 -> 501501.74 | U10: =IPMT($U$3/12,S10,$U$2,($U$1)) -> -347716.09 | V10: =T10+U10 -> 153785.65 | Y10: 4 | Z10: =$AA$4 -> 143286.21 | AA10: =IPMT($AA$3/12,Y10,$AA$2,($AA$1)) -> -99347.455 | AB10: =Z10+AA10 -> 43938.757 | AE10: 4 | AF10: =$AG$4 -> 586008.13 | AG10: =IPMT($AG$3/12,AE10,$AG$2,($AG$1)) -> -293516.43 | AH10: =AF10+AG10 -> 292491.7
